<?xml version="1.0"?>
<robot xmlns:xacro="http://www.ros.org/wiki/xacro">

    <gazebo reference="chassis">
        <material>Gazebo/White</material>
    </gazebo>

    <gazebo reference="left_wheel">
        <material>Gazebo/Blue</material>
    </gazebo>

    <gazebo reference="right_wheel">
        <material>Gazebo/Blue</material>
    </gazebo>

    <gazebo reference="caster_wheel">
        <material>Gazebo/Black</material>
        <mu1 value = "0.001" />
        <mu2 value = "0.001" />
    </gazebo>

    <!-- Example link -->
    <xacro:include filename="inertial_macros.xacro"/>

    <joint name="base_footprint_joint" type="fixed">
        <parent link="base_link"/>
        <child link="base_footprint"/>
        <origin xyz="0 0 0"/>    
    </joint>

    <!-- Example link -->
    <link name="base_footprint">
    </link>
    
    <!-- Example link -->
    <link name="base_link">
    </link>

    <joint name="base_link" type="fixed">
        <parent link="base_link"/>
        <child link="chassis"/>
        <origin xyz="-0.1 0 0"/>    
    </joint>

    <!-- chassis link -->
    <link name="chassis">
        <visual>
            <origin xyz="0.15 0 0.075"/>
            <geometry>
                <box size="0.3 0.3 0.15"/>
            </geometry>
            <material name="white"/>
        </visual>
        <collision>
            <origin xyz="0.15 0 0.075"/>
            <geometry>
                <box size="0.3 0.3 0.15"/>
            </geometry>
        </collision>
        <xacro:inertial_box mass="0.5" x="0.3" y="0.3" z="0.15">
            <origin xyz="0.15 0 0.075" rpy="0 0 0"/>
        </xacro:inertial_box>
    </link>

    <!-- left wheel joint -->
    <joint name="left_wheel_joint" type="continuous">
        <parent link="base_link"/>
        <child link="left_wheel"/>
        <origin xyz="0 0.175 0" rpy="-${pi/2} 0 0"/>
        <axis xyz="0 0 1"/>    
    </joint>

    <!-- left wheel link -->
    <link name="left_wheel">
        <visual>
            <geometry>
                <cylinder radius="0.05" length="0.04"/>
            </geometry>
            <material name="blue"/>
        </visual>
        <collision>
            <geometry>
                <cylinder radius="0.05" length="0.04"/>
            </geometry>
        </collision>
        <xacro:inertial_cylinder mass="0.1" length="0.04" radius="0.05">
            <origin xyz="0 0 0" rpy="0 0 0"/>
        </xacro:inertial_cylinder>
        <collision>
            <geometry>
                <sphere radius="0.05"/>
            </geometry>
        </collision>
    </link>

    <!-- right wheel joint -->
    <joint name="right_wheel_joint" type="continuous">
        <parent link="base_link"/>
        <child link="right_wheel"/>
        <origin xyz="0 -0.175 0" rpy="${pi/2} 0 0"/>
        <axis xyz="0 0 -1"/>    
    </joint>

    <!-- right wheel link -->
    <link name="right_wheel">
        <visual>
            <geometry>
                <cylinder radius="0.05" length="0.04"/>
            </geometry>
            <material name="blue"/>
        </visual>
        <collision>
            <geometry>
                <cylinder radius="0.05" length="0.04"/>
            </geometry>
        </collision>
        <xacro:inertial_cylinder mass="0.1" length="0.04" radius="0.05">
            <origin xyz="0 0 0" rpy="0 0 0"/>
        </xacro:inertial_cylinder>
        <collision>
            <geometry>
                <sphere radius="0.05"/>
            </geometry>
        </collision>
    </link>

    <!-- caster wheel joint -->
    <joint name="caster_wheel_joint" type="fixed">
        <parent link="chassis"/>
        <child link="caster_wheel"/>
        <origin xyz="0.24 0 0"/>  
    </joint>

    <!-- caster wheel link -->
    <link name="caster_wheel">
        <visual>
            <geometry>
                <sphere radius="0.05"/>
            </geometry>
            <material name="black"/>
        </visual>
        <collision>
            <geometry>
                <sphere radius="0.05"/>
            </geometry>
        </collision>
        <xacro:inertial_sphere mass="0.5" radius="0.05">
            <origin xyz="0 0 0" rpy="0 0 0"/>
        </xacro:inertial_sphere>

    </link>

</robot>